Workbook

Sheet qwen3_08B
A1: id | B1: question | C1: relv | D1: ret_chunks | E1: acc_1 | F1: acc_2 | G1: acc_3 | H1: acc_4 | I1: acc_5 | J1: acc_6 | K1: acc_7 | L1: acc_8 | M1: acc_9 | N1: acc_10
A2: 0 | B2: Какой вес имеет "Висячий камень" в парке Ергаки? | C2: [90, 123, 149, 190] | D2: [123, 90, 149, 190, 123, 190, 89, 47, 149, 190] | E2: 1 | F2: 1 | G2: 0.66666667 | H2: 0.75 | I2: 0.6 | J2: 0.66666667 | K2: 0.71428571 | L2: 0.75 | M2: 0.77777778 | N2: 0.8
A3: 1 | B3: Какова длина "Висячего камня" в парке Ергаки? | C3: [90, 123, 149, 190] | D3: [190, 123, 90, 47, 190, 89, 149, 149, 190, 90] | E3: 1 | F3: 1 | G3: 0.66666667 | H3: 0.75 | I3: 0.6 | J3: 0.66666667 | K3: 0.71428571 | L3: 0.75 | M3: 0.77777778 | N3: 0.8
A4: 2 | B4: Сколько ступеней в лестнице музея "Оглахты"? | C4: [47, 48, 89, 90, 147, 151] | D4: [149, 90, 47, 48, 147, 120, 122, 175, 151, 321] | E4: 0 | F4: 0.5 | G4: 0.66666667 | H4: 0.75 | I4: 0.8 | J4: 0.66666667 | K4: 0.57142857 | L4: 0.5 | M4: 0.55555556 | N4: 0.5
A5: 3 | B5: Сколько видов сыра предлагает сыроварня Deutsches Haus в Немане? | C5: [33] | D5: [307, 33, 309, 311, 310, 312, 90, 261, 240, np.int64(31)] | E5: 1 | F5: 0.5 | G5: 0.33333333 | H5: 0.25 | I5: 0.2 | J5: 0.16666667 | K5: 0.14285714 | L5: 0.125 | M5: 0.11111111 | N5: 0.1
A6: 4 | B6: Сколько экспонатов в собрании Национального музея Республики Татарстан? | C6: [39] | D6: [152, 18, 39, 13, 20, 19, 154, 155, np.int64(155), np.int64(47)] | E6: 0 | F6: 0 | G6: 0 | H6: 0 | I6: 0 | J6: 0 | K6: 0.14285714 | L6: 0.125 | M6: 0.11111111 | N6: 0.1
A7: 5 | B7: Сколько порогов проходят при сплаве по реке Катунь? | C7: [30, 31] | D7: [29, 30, 215, 218, 193, 93, np.int64(29), np.int64(193), np.int64(192), np.int64(157)] | E7: 1 | F7: 1 | G7: 0.33333333 | H7: 0.25 | I7: 0.2 | J7: 0.16666667 | K7: 0.28571429 | L7: 0.25 | M7: 0.11111111 | N7: 0.1
A8: 6 | B8: Сколько островов входит в экскурсию "Семь чудес Чивыркуйского залива"? | C8: [41] | D8: [288, 41, 105, 124, 49, 139, 46, 214, 83, np.int64(181)] | E8: 1 | F8: 0.5 | G8: 0.33333333 | H8: 0.25 | I8: 0.2 | J8: 0.16666667 | K8: 0.14285714 | L8: 0.125 | M8: 0.11111111 | N8: 0.1
A9: 7 | B9: Сколько бухт посещают во время экскурсии "Семь чудес Чивыркуйского залива"? | C9: [41] | D9: [29, 362, 365, 41, 216, 199, np.int64(180), np.int64(213), np.int64(182), np.int64(182)] | E9: 1 | F9: 0.5 | G9: 0.33333333 | H9: 0.25 | I9: 0.2 | J9: 0.16666667 | K9: 0.14285714 | L9: 0.125 | M9: 0.11111111 | N9: 0.1
A10: 8 | B10: Сколько источников с целебной водой можно попробовать на курорте "Марциальные Воды"? | C10: [9, 58, 156] | D10: [9, 156, 134, 9, 179, 209, 84, 82, 225, np.int64(114)] | E10: 1 | F10: 1 | G10: 0.66666667 | H10: 0.5 | I10: 0.4 | J10: 0.33333333 | K10: 0.28571429 | L10: 0.25 | M10: 0.33333333 | N10: 0.3
A11: 9 | B11: Сколько живописных и графических работ представлено в галерее Константина Васильева? | C11: [15] | D11: [152, 14, 15, 15, 15, 154, np.int64(223), np.int64(209), np.int64(182), np.int64(41)] | E11: 1 | F11: 1 | G11: 1 | H11: 0.5 | I11: 0.4 | J11: 0.33333333 | K11: 0.28571429 | L11: 0.375 | M11: 0.33333333 | N11: 0.3
E12: =AVERAGE(E2:E11) -> 0.8 | F12: =AVERAGE(F2:F11) -> 0.7 | G12: =AVERAGE(G2:G11) -> 0.5 | H12: =AVERAGE(H2:H11) -> 0.425 | I12: =AVERAGE(I2:I11) -> 0.36 | J12: =AVERAGE(J2:J11) -> 0.33333333 | K12: =AVERAGE(K2:K11) -> 0.34285714 | L12: =AVERAGE(L2:L11) -> 0.3375 | ... N12: =AVERAGE(N2:N11) -> 0.32
A13: 0 | B13: Где хранится самый большой печатный Коран в мире, хранящийся в Болгаре? | C13: [12, 13, 16, 17, 18] | D13: [16, 365, 13, 17, 12, 149, 139, 17, np.int64(28), np.int64(142)] | E13: 1 | F13: 1 | G13: 1 | H13: 1 | I13: 1 | J13: 0.66666667 | K13: 0.57142857 | L13: 0.625 | M13: 0.55555556 | N13: 0.5
A14: 1 | B14: Какой минерал является гордостью Карелии | C14: [9, 156] | D14: [9, 156, 90, 138, 156, 156, 145, 191, 156, np.int64(21)] | E14: 0 | F14: 1 | G14: 1 | H14: 0.75 | I14: 0.6 | J14: 0.66666667 | K14: 0.71428571 | L14: 0.5 | M14: 0.44444444 | N14: 0.5
A15: 2 | B15: Какой тип пения демонстрируют в Тувинском национальном музыкальном центре? | C15: [45, 90, 123, 149, 150] | D15: [90, 149, 45, 123, 150, 90, 150, 45, 123, np.int64(16)] | E15: 1 | F15: 1 | G15: 1 | H15: 0.75 | I15: 0.8 | J15: 0.83333333 | K15: 0.85714286 | L15: 0.875 | M15: 0.88888889 | N15: 0.9
A16: 3 | B16: Какой напиток предлагают гостям в усадьбе Бюргера в Выборге? | C16: [8] | D16: [8, 99, 99, 99, 8, 99, 134, 286, 82, 359] | E16: 1 | F16: 0.5 | G16: 0.33333333 | H16: 0.5 | I16: 0.4 | J16: 0.33333333 | K16: 0.28571429 | L16: 0.25 | M16: 0.22222222 | N16: 0.2
A17: 4 | B17: Как называется традиционная тувинская выпечка, которую подают на ужине? | C17: [45, 90, 149, 150] | D17: [90, 150, 45, 90, 149, 149, 123, 45, 81, np.int64(153)] | E17: 1 | F17: 1 | G17: 1 | H17: 1 | I17: 1 | J17: 0.83333333 | K17: 0.85714286 | L17: 0.875 | M17: 0.77777778 | N17: 0.7
A18: 5 | B18: Как называется традиционная бурятская еда, которую подают в Тункинской долине? | C18: [45, 90, 149, 150] | D18: [42, 122, 122, 121, 196, 191, 137, 150, 149, 30] | E18: 0 | F18: 0 | G18: 0 | H18: 0 | I18: 0 | J18: 0 | K18: 0 | L18: 0.125 | M18: 0.22222222 | N18: 0.2
A19: 6 | B19: Как называется место в Хакасии, где можно увидеть след Будды? | C19: [45, 90, 149, 150] | D19: [149, 150, 123, 90, 45, 191, 139, 45, 50, 42] | E19: 1 | F19: 1 | G19: 0.66666667 | H19: 0.5 | I19: 0.6 | J19: 0.66666667 | K19: 0.57142857 | L19: 0.625 | M19: 0.55555556 | N19: 0.5
A20: 7 | B20: Какое поэтическое название используют для Телецкого озера в описаниях туров? | C20: [29, 30, 31, 92, 93, 94, 159, 194, 215, 216, 218] | D20: [92, 215, 30, 93, 215, 93, np.int64(171), np.int64(5), np.int64(224), np.int64(225)] | E20: 1 | F20: 1 | G20: 0.66666667 | H20: 0.75 | I20: 0.75 | J20: 0.66666667 | K20: 0.71428571 | L20: 0.625 | M20: 0.66666667 | N20: 0.6
A21: 8 | B21: Какая из буддийских ступ расположена на острове Огой? | C21: [57, 120, 124, 185] | D21: [122, 175, 50, 121, 69, 51, 137, 138, 120, 149] | E21: 0 | F21: 0 | G21: 0 | H21: 0 | I21: 0 | J21: 0 | K21: 0 | L21: 0.125 | M21: 0.11111111 | N21: 0.1
A22: 9 | B22: Какой уникальный архитектурный стиль характеризует библиотеку Алвара Аалто в Выборге? | C22: [8] | D22: [8, 99, 8, 18, 8, 149, 327, 267, 93, 265] | E22: 1 | F22: 0.5 | G22: 0.66666667 | H22: 0.5 | I22: 0.6 | J22: 0.5 | K22: 0.42857143 | L22: 0.375 | M22: 0.33333333 | N22: 0.3
E23: =AVERAGE(E13:E22) -> 0.7 | F23: =AVERAGE(F13:F22) -> 0.7 | G23: =AVERAGE(G13:G22) -> 0.63333333 | H23: =AVERAGE(H13:H22) -> 0.575 | I23: =AVERAGE(I13:I22) -> 0.575 | J23: =AVERAGE(J13:J22) -> 0.51666667 | K23: =AVERAGE(K13:K22) -> 0.5 | L23: =AVERAGE(L13:L22) -> 0.5 | ... N23: =AVERAGE(N13:N22) -> 0.45
A24: 0 | B24: Какие два моста являются символами Владивостока? | C24: [46, 118, 119, 182, 183, 184, 196, 212, 213, 214] | D24: [119, 183, 214, 119, 212, 118, 184, 212, 182, 183] | E24: 1 | F24: 1 | G24: 1 | H24: 1 | I24: 1 | J24: 1 | K24: 1 | L24: 1 | M24: 1 | N24: 1
A25: 1 | B25: Какие залы можно осмотреть в Храме всех религий? | C25: [13, 39, 40, 54, 55, 152, 153, 154, 155] | D25: [246, 40, 228, 13, 231, 240, np.int64(191), np.int64(54), np.int64(108), np.int64(5)] | E25: 1 | F25: 1 | G25: 0.66666667 | H25: 0.5 | I25: 0.4 | J25: 0.5 | K25: 0.42857143 | L25: 0.375 | M25: 0.33333333 | N25: 0.3
A26: 2 | B26: Блюда из каких виды морских обитателей дегустируют во Владивостоке? | C26: [46, 196, 212, 213] | D26: [46, 213, 212, 196, 214, 196, 118, 183, 119, 196] | E26: 1 | F26: 1 | G26: 1 | H26: 1 | I26: 0.8 | J26: 0.83333333 | K26: 0.71428571 | L26: 0.625 | M26: 0.55555556 | N26: 0.6
A27: 3 | B27: Какие животные обитают в сафари-парке Шкотово? | C27: [46, 118, 119, 214] | D27: [119, 196, 214, 46, 214, 118, 182, 118, 172, 201] | E27: 1 | F27: 1 | G27: 1 | H27: 1 | I27: 0.8 | J27: 0.83333333 | K27: 0.71428571 | L27: 0.75 | M27: 0.66666667 | N27: 0.6
A28: 4 | B28: Что чаще всего посещают во время экскурсии в Царское Село? | C28: [3, 4, 6, 7, 27, 28, 44, 201] | D28: [27, 27, 3, 6, 44, 201, 4, 0, np.int64(4), np.int64(88)] | E28: 1 | F28: 1 | G28: 1 | H28: 1 | I28: 1 | J28: 1 | K28: 1 | L28: 0.875 | M28: 0.88888889 | N28: 0.8
A29: 5 | B29: Что включает в себя экскурсия в Эрмитаж? | C29: [2, 3, 4, 5, 6, 7, 28, 44, 99, 125, 201] | D29: [307, 201, 3, 28, 2, 99, 6, 305, np.int64(201), np.int64(7)] | E29: 1 | F29: 1 | G29: 1 | H29: 1 | I29: 1 | J29: 1 | K29: 0.85714286 | L29: 0.875 | M29: 0.88888889 | N29: 0.8
A30: 6 | B30: Какие объекты посещают во время экскурсии по Свияжску? | C30: [10, 11, 12, 13, 14, 15, 16, 17, 18, 19, 20, 40, 54, 55, 152, 153, 154, 155] | D30: [10, 14, 40, 152, np.int64(30), np.int64(51), np.int64(191), np.int64(175), np.int64(15), np.int64(50)] | E30: 1 | F30: 0.5 | G30: 0.66666667 | H30: 0.5 | I30: 0.4 | J30: 0.5 | K30: 0.42857143 | L30: 0.5 | M30: 0.55555556 | N30: 0.5
A31: 7 | B31: Какие сувениры можно приобрести в Йошкар-Оле? | C31: [16, 17, 18, 19, 20] | D31: [128, 16, 17, 19, 90, 68, 50, np.int64(30), np.int64(113), np.int64(218)] | E31: 1 | F31: 1 | G31: 1 | H31: 0.75 | I31: 0.6 | J31: 0.5 | K31: 0.42857143 | L31: 0.375 | M31: 0.33333333 | N31: 0.3
A32: 8 | B32: на что можно посмотреть в Кунсткамере? | C32: [23, 24, 25, 26, 27, 28] | D32: [153, 310, 37, 45, 154, 152, 54, np.int64(223), np.int64(138), np.int64(170)] | E32: 0 | F32: 0 | G32: 0 | H32: 0 | I32: 0 | J32: 0 | K32: 0 | L32: 0 | M32: 0 | N32: 0
A33: 9 | B33: Как называются постройки на острове Кижи? | C33: [44] | D33: [44, 69, 175, 50, 13, 54, 137, 113, 51, 184] | E33: 1 | F33: 0.5 | G33: 0.33333333 | H33: 0.25 | I33: 0.2 | J33: 0.16666667 | K33: 0.14285714 | L33: 0.125 | M33: 0.11111111 | N33: 0.1
E34: =AVERAGE(E24:E33) -> 0.9 | F34: =AVERAGE(F24:F33) -> 0.8 | G34: =AVERAGE(G24:G33) -> 0.76666667 | H34: =AVERAGE(H24:H33) -> 0.7 | I34: =AVERAGE(I24:I33) -> 0.62 | J34: =AVERAGE(J24:J33) -> 0.63333333 | K34: =AVERAGE(K24:K33) -> 0.57142857 | L34: =AVERAGE(L24:L33) -> 0.55 | ... N34: =AVERAGE(N24:N33) -> 0.5
A35: 0 | B35: хочу тур по культурной столице России, с посещением окрестных достопримечательностей | C35: [2, 3, 4, 5, 6, 7, 8, 23, 24, 25, 26, 27, 28, 125, 126, 201] | D35: [310, 108, 116, 20, 13, 19, np.int64(117), 109, 130, 309] | E35: 0 | F35: 0 | G35: 0 | H35: 0 | I35: 0 | J35: 0 | K35: 0 | L35: 0 | M35: 0 | N35: 0
A36: 1 | B36: Интересует тур в один из древнейших городов России, связанный имуществом родителей величайшего поэтв золотого века российской литературы | C36: [100, 101, 102, 103, 104, 105, 106, 107] | D36: [108, 116, 109, 108, 154, 230, 46, 114, 18, np.int64(115)] | E36: 0 | F36: 0 | G36: 0 | H36: 0 | I36: 0 | J36: 0 | K36: 0 | L36: 0 | M36: 0 | N36: 0
A37: 2 | B37: тур по северо-западу России, с посещением мест, где река с грохотом обрушивается вниз, старинного курорта с целебными источниками и обзорной экскурсией по столице региона. | C37: [9, 44, 58, 156, 201] | D37: [180, 9, 108, 109, 130, 156, 122, 67, np.int64(16), np.int64(6)] | E37: 0 | F37: 0 | G37: 0 | H37: 0 | I37: 0.2 | J37: 0.16666667 | K37: 0.14285714 | L37: 0.25 | M37: 0.22222222 | N37: 0.2
A38: 3 | B38: Ищу тур по главному городу Приморья с обзорной экскурсией по центру и парку дикой природы с дальневосточными животными | C38: [46, 118, 119, 182, 183, 184, 196, 212, 213, 214] | D38: [213, 118, 196, 306, 305, 304, 172, 9, 176, 46] | E38: 1 | F38: 0.5 | G38: 0.33333333 | H38: 0.25 | I38: 0.2 | J38: 0.33333333 | K38: 0.28571429 | L38: 0.375 | M38: 0.33333333 | N38: 0.4
A39: 4 | B39: тур по столице России, включающий в себя наиболее популярные достопримечательности | C39: [0, 1] | D39: [316, 108, 109, 306, 116, 304, 314, 305, 290, np.int64(153)] | E39: 0 | F39: 0 | G39: 0 | H39: 0 | I39: 0 | J39: 0 | K39: 0 | L39: 0 | M39: 0 | N39: 0
A40: 5 | B40: тур по северо-западу России, по местам добычи минералов, известных своими целебными свойствами | C40: [9, 156] | D40: [58, 156, 122, 109, 121, 108, 215, 120, 90, 94] | E40: 0 | F40: 0.5 | G40: 0.33333333 | H40: 0.25 | I40: 0.2 | J40: 0.16666667 | K40: 0.14285714 | L40: 0.125 | M40: 0.11111111 | N40: 0.1
...

Sheet e5
A1: id | B1: question | C1: relv | D1: ret_chunks | E1: acc_1 | F1: acc_2 | G1: acc_3 | H1: acc_4 | I1: acc_5 | J1: acc_6 | K1: acc_7 | L1: acc_8 | M1: acc_9 | N1: acc_10
A2: 0 | B2: Какой вес имеет "Висячий камень" в парке Ергаки? | C2: [90, 123, 149, 190] | D2: [np.int64(123), np.int64(149), np.int64(190), np.int64(90), np.int64(123), np.int64(123), np.int64(58), np.int64(156), np.int64(90), np.int64(149)] | E2: 1 | F2: 1 | G2: 1 | H2: 1 | I2: 1 | J2: 1 | K2: 0.85714286 | L2: 0.75 | M2: 0.77777778 | N2: 0.8
A3: 1 | B3: Какова длина "Висячего камня" в парке Ергаки? | C3: [90, 123, 149, 190] | D3: [np.int64(123), np.int64(151), np.int64(58), np.int64(89), np.int64(156), np.int64(90), np.int64(149), np.int64(190), np.int64(156), np.int64(118)] | E3: 1 | F3: 0.5 | G3: 0.33333333 | H3: 0.25 | I3: 0.2 | J3: 0.33333333 | K3: 0.42857143 | L3: 0.5 | M3: 0.44444444 | N3: 0.4
A4: 2 | B4: Сколько ступеней в лестнице музея "Оглахты"? | C4: [47, 48, 89, 90, 147, 151] | D4: [np.int64(90), np.int64(48), np.int64(149), np.int64(47), np.int64(147), np.int64(47), np.int64(89), np.int64(149), np.int64(147), np.int64(9)] | E4: 1 | F4: 1 | G4: 0.66666667 | H4: 0.75 | I4: 0.8 | J4: 0.83333333 | K4: 0.85714286 | L4: 0.75 | M4: 0.77777778 | N4: 0.7
A5: 3 | B5: Сколько видов сыра предлагает сыроварня Deutsches Haus в Немане? | C5: [33] | D5: [np.int64(31), np.int64(33), np.int64(76), np.int64(74), np.int64(72), np.int64(79), np.int64(87), np.int64(88), np.int64(218)] | E5: 1 | F5: 0.5 | G5: 0.33333333 | H5: 0.25 | I5: 0.2 | J5: 0.16666667 | K5: 0.16666667 | L5: 0.14285714 | M5: 0.125 | N5: 0.11111111
A6: 4 | B6: Сколько экспонатов в собрании Национального музея Республики Татарстан? | C6: [39] | D6: [np.int64(39), np.int64(18), np.int64(155), np.int64(47), np.int64(182), np.int64(213), np.int64(58), np.int64(118), np.int64(127), np.int64(184)] | E6: 1 | F6: 0.5 | G6: 0.33333333 | H6: 0.25 | I6: 0.2 | J6: 0.16666667 | K6: 0.14285714 | L6: 0.125 | M6: 0.11111111 | N6: 0.1
A7: 5 | B7: Сколько порогов проходят при сплаве по реке Катунь? | C7: [30, 31] | D7: [np.int64(30), np.int64(29), np.int64(193), np.int64(192), np.int64(218), np.int64(157), np.int64(158), np.int64(193), np.int64(159)] | E7: 1 | F7: 1 | G7: 0.5 | H7: 0.33333333 | I7: 0.25 | J7: 0.2 | K7: 0.16666667 | L7: 0.14285714 | M7: 0.125 | N7: 0.11111111
A8: 6 | B8: Сколько островов входит в экскурсию "Семь чудес Чивыркуйского залива"? | C8: [41] | D8: [np.int64(181), np.int64(41), np.int64(184), np.int64(163), np.int64(212), np.int64(118), np.int64(2), np.int64(225), np.int64(115)] | E8: 1 | F8: 0.5 | G8: 0.33333333 | H8: 0.25 | I8: 0.2 | J8: 0.2 | K8: 0.16666667 | L8: 0.14285714 | M8: 0.125 | N8: 0.11111111
A9: 7 | B9: Сколько бухт посещают во время экскурсии "Семь чудес Чивыркуйского залива"? | C9: [41] | D9: [np.int64(180), np.int64(41), np.int64(213), np.int64(182), np.int64(182), np.int64(126), np.int64(212), np.int64(5), np.int64(174)] | E9: 1 | F9: 0.5 | G9: 0.33333333 | H9: 0.25 | I9: 0.2 | J9: 0.2 | K9: 0.16666667 | L9: 0.14285714 | M9: 0.125 | N9: 0.11111111
A10: 8 | B10: Сколько источников с целебной водой можно попробовать на курорте "Марциальные Воды"? | C10: [9, 58, 156] | D10: [np.int64(156), np.int64(114), np.int64(108), np.int64(109), np.int64(82), np.int64(205), np.int64(163), np.int64(134), np.int64(9), np.int64(166)] | E10: 1 | F10: 0.5 | G10: 0.33333333 | H10: 0.25 | I10: 0.2 | J10: 0.16666667 | K10: 0.14285714 | L10: 0.125 | M10: 0.22222222 | N10: 0.2
A11: 9 | B11: Сколько живописных и графических работ представлено в галерее Константина Васильева? | C11: [15] | D11: [np.int64(15), np.int64(15), np.int64(223), np.int64(209), np.int64(182), np.int64(41), np.int64(206), np.int64(176), np.int64(166), np.int64(187)] | E11: 1 | F11: 1 | G11: 0.66666667 | H11: 0.5 | I11: 0.4 | J11: 0.33333333 | K11: 0.28571429 | L11: 0.25 | M11: 0.22222222 | N11: 0.2
E12: =AVERAGE(E2:E11) -> 1 | F12: =AVERAGE(F2:F11) -> 0.7 | G12: =AVERAGE(G2:G11) -> 0.48333333 | H12: =AVERAGE(H2:H11) -> 0.40833333 | I12: =AVERAGE(I2:I11) -> 0.365 | J12: =AVERAGE(J2:J11) -> 0.36 | K12: =AVERAGE(K2:K11) -> 0.33809524 | L12: =AVERAGE(L2:L11) -> 0.30714286 | ... N12: =AVERAGE(N2:N11) -> 0.28444444
A13: 0 | B13: Где хранится самый большой печатный Коран в мире, хранящийся в Болгаре? | C13: [12, 13, 16, 17, 18] | D13: [np.int64(28), np.int64(18), np.int64(13), np.int64(12), np.int64(17), np.int64(142)] | E13: 1 | F13: 1 | G13: 1 | H13: 1 | I13: 1 | J13: 0.8 | K13: 0.66666667 | L13: 0.66666667 | M13: 0.66666667 | N13: 0.66666667
A14: 1 | B14: Какой минерал является гордостью Карелии | C14: [9, 156] | D14: [np.int64(21), np.int64(9), np.int64(156), np.int64(156), np.int64(42), np.int64(194), np.int64(42), np.int64(7), np.int64(186)] | E14: 1 | F14: 1 | G14: 1 | H14: 0.75 | I14: 0.6 | J14: 0.5 | K14: 0.42857143 | L14: 0.42857143 | M14: 0.375 | N14: 0.33333333
A15: 2 | B15: Какой тип пения демонстрируют в Тувинском национальном музыкальном центре? | C15: [45, 90, 123, 149, 150] | D15: [np.int64(90), np.int64(16), np.int64(17), np.int64(45), np.int64(123), np.int64(149), np.int64(18), np.int64(20), np.int64(19)] | E15: 0 | F15: 0 | G15: 0.33333333 | H15: 0.5 | I15: 0.5 | J15: 0.6 | K15: 0.66666667 | L15: 0.57142857 | M15: 0.5 | N15: 0.44444444
A16: 3 | B16: Какой напиток предлагают гостям в усадьбе Бюргера в Выборге? | C16: [8] | D16: [np.int64(8), np.int64(99), np.int64(99), np.int64(105), np.int64(104), np.int64(137), np.int64(123), np.int64(90), np.int64(45), np.int64(89)] | E16: 1 | F16: 0.5 | G16: 0.33333333 | H16: 0.25 | I16: 0.2 | J16: 0.16666667 | K16: 0.14285714 | L16: 0.125 | M16: 0.11111111 | N16: 0.1
A17: 4 | B17: Как называется традиционная тувинская выпечка, которую подают на ужине? | C17: [45, 90, 149, 150] | D17: [np.int64(153), np.int64(15), np.int64(149), np.int64(147), np.int64(223), np.int64(89), np.int64(93)] | E17: 1 | F17: 0.5 | G17: 0.33333333 | H17: 0.25 | I17: 0.2 | J17: 0.16666667 | K17: 0.16666667 | L17: 0.14285714 | M17: 0.14285714 | N17: 0.14285714
A18: 5 | B18: Как называется традиционная бурятская еда, которую подают в Тункинской долине? | C18: [45, 90, 149, 150] | D18: [np.int64(155), np.int64(15), np.int64(42), np.int64(183), np.int64(223), np.int64(191), np.int64(89)] | E18: 0 | F18: 0 | G18: 0 | H18: 0 | I18: 0 | J18: 0 | K18: 0 | L18: 0 | M18: 0 | N18: 0
A19: 6 | B19: Как называется место в Хакасии, где можно увидеть след Будды? | C19: [45, 90, 149, 150] | D19: [np.int64(15), np.int64(123), np.int64(150), np.int64(90), np.int64(45), np.int64(149), np.int64(147), np.int64(89), np.int64(223)] | E19: 0 | F19: 0.5 | G19: 0.66666667 | H19: 0.75 | I19: 0.8 | J19: 0.66666667 | K19: 0.57142857 | L19: 0.5 | M19: 0.44444444 | N19: 0.44444444
A20: 7 | B20: Какое поэтическое название используют для Телецкого озера в описаниях туров? | C20: [29, 30, 31, 92, 93, 94, 159, 194, 215, 216, 218] | D20: [np.int64(159), np.int64(171), np.int64(5), np.int64(93), np.int64(224), np.int64(225), np.int64(9)] | E20: 0 | F20: 0.5 | G20: 0.66666667 | H20: 0.66666667 | I20: 0.66666667 | J20: 0.5 | K20: 0.4 | L20: 0.33333333 | M20: 0.28571429 | N20: 0.28571429
A21: 8 | B21: Какая из буддийских ступ расположена на острове Огой? | C21: [57, 120, 124, 185] | D21: [np.int64(122), np.int64(121), np.int64(69), np.int64(137), np.int64(51), np.int64(50), np.int64(175), np.int64(121), np.int64(138), np.int64(138)] | E21: 0 | F21: 0 | G21: 0 | H21: 0 | I21: 0 | J21: 0 | K21: 0 | L21: 0 | M21: 0 | N21: 0
A22: 9 | B22: Какой уникальный архитектурный стиль характеризует библиотеку Алвара Аалто в Выборге? | C22: [8] | D22: [np.int64(8), np.int64(8), np.int64(99), np.int64(155), np.int64(18), np.int64(39), np.int64(11), np.int64(15), np.int64(54), np.int64(126)] | E22: 1 | F22: 1 | G22: 0.66666667 | H22: 0.5 | I22: 0.4 | J22: 0.33333333 | K22: 0.28571429 | L22: 0.25 | M22: 0.22222222 | N22: 0.2
E23: =AVERAGE(E13:E22) -> 0.5 | F23: =AVERAGE(F13:F22) -> 0.5 | G23: =AVERAGE(G13:G22) -> 0.5 | H23: =AVERAGE(H13:H22) -> 0.46666667 | I23: =AVERAGE(I13:I22) -> 0.43666667 | J23: =AVERAGE(J13:J22) -> 0.37333333 | K23: =AVERAGE(K13:K22) -> 0.33285714 | L23: =AVERAGE(L13:L22) -> 0.30178571 | ... N23: =AVERAGE(N13:N22) -> 0.26174603
A24: 0 | B24: Какие два моста являются символами Владивостока? | C24: [46, 118, 119, 182, 183, 184, 196, 212, 213, 214] | D24: [np.int64(182), np.int64(212), np.int64(119), np.int64(214), np.int64(212), np.int64(119), np.int64(15), np.int64(147), np.int64(183), np.int64(51)] | E24: 1 | F24: 1 | G24: 1 | H24: 1 | I24: 1 | J24: 1 | K24: 0.85714286 | L24: 0.75 | M24: 0.77777778 | N24: 0.7
A25: 1 | B25: Какие залы можно осмотреть в Храме всех религий? | C25: [13, 39, 40, 54, 55, 152, 153, 154, 155] | D25: [np.int64(40), np.int64(191), np.int64(54), np.int64(108), np.int64(13), np.int64(5), np.int64(15), np.int64(36), np.int64(99)] | E25: 0 | F25: 0.5 | G25: 0.33333333 | H25: 0.5 | I25: 0.5 | J25: 0.6 | K25: 0.5 | L25: 0.42857143 | M25: 0.375 | N25: 0.33333333
A26: 2 | B26: Блюда из каких виды морских обитателей дегустируют во Владивостоке? | C26: [46, 196, 212, 213] | D26: [np.int64(224), np.int64(184), np.int64(183), np.int64(139), np.int64(170), np.int64(213), np.int64(196), np.int64(50), np.int64(105)] | E26: 0 | F26: 0 | G26: 0 | H26: 0 | I26: 0 | J26: 0 | K26: 0.16666667 | L26: 0.28571429 | M26: 0.25 | N26: 0.22222222
A27: 3 | B27: Какие животные обитают в сафари-парке Шкотово? | C27: [46, 118, 119, 214] | D27: [np.int64(165), np.int64(178), np.int64(196), np.int64(15), np.int64(214), np.int64(119), np.int64(50), np.int64(46), np.int64(175), np.int64(191)] | E27: 0 | F27: 0 | G27: 0 | H27: 0 | I27: 0.2 | J27: 0.33333333 | K27: 0.28571429 | L27: 0.375 | M27: 0.33333333 | N27: 0.3
A28: 4 | B28: Что чаще всего посещают во время экскурсии в Царское Село? | C28: [3, 4, 6, 7, 27, 28, 44, 201] | D28: [np.int64(28), np.int64(6), np.int64(44), np.int64(201), np.int64(3), np.int64(4), np.int64(88), np.int64(7), np.int64(28)] | E28: 1 | F28: 1 | G28: 1 | H28: 1 | I28: 1 | J28: 1 | K28: 1 | L28: 0.85714286 | M28: 0.875 | N28: 0.88888889
A29: 5 | B29: Что включает в себя экскурсия в Эрмитаж? | C29: [2, 3, 4, 5, 6, 7, 28, 44, 99, 125, 201] | D29: [np.int64(201), np.int64(7), np.int64(201), np.int64(3), np.int64(28), np.int64(120), np.int64(44), np.int64(3), np.int64(4), np.int64(151)] | E29: 1 | F29: 1 | G29: 1 | H29: 1 | I29: 1 | J29: 0.83333333 | K29: 0.85714286 | L29: 0.875 | M29: 0.88888889 | N29: 0.8
A30: 6 | B30: Какие объекты посещают во время экскурсии по Свияжску? | C30: [10, 11, 12, 13, 14, 15, 16, 17, 18, 19, 20, 40, 54, 55, 152, 153, 154, 155] | D30: [np.int64(30), np.int64(51), np.int64(191), np.int64(175), np.int64(15), np.int64(50), np.int64(9), np.int64(68)] | E30: 0 | F30: 0 | G30: 0 | H30: 0.25 | I30: 0.2 | J30: 0.16666667 | K30: 0.16666667 | L30: 0.16666667 | M30: 0.14285714 | N30: 0.125
A31: 7 | B31: Какие сувениры можно приобрести в Йошкар-Оле? | C31: [16, 17, 18, 19, 20] | D31: [np.int64(30), np.int64(113), np.int64(218), np.int64(127), np.int64(217), np.int64(56), np.int64(47), np.int64(61), np.int64(59)] | E31: 0 | F31: 0 | G31: 0 | H31: 0 | I31: 0 | J31: 0 | K31: 0 | L31: 0 | M31: 0 | N31: 0
A32: 8 | B32: на что можно посмотреть в Кунсткамере? | C32: [23, 24, 25, 26, 27, 28] | D32: [np.int64(223), np.int64(138), np.int64(45), np.int64(170), np.int64(67), np.int64(197), np.int64(59), np.int64(31), np.int64(225), np.int64(69)] | E32: 0 | F32: 0 | G32: 0 | H32: 0 | I32: 0 | J32: 0 | K32: 0 | L32: 0 | M32: 0 | N32: 0
A33: 9 | B33: Как называются постройки на острове Кижи? | C33: [44] | D33: [np.int64(153), np.int64(14), np.int64(44), np.int64(44), np.int64(197), np.int64(5), np.int64(15)] | E33: 1 | F33: 1 | G33: 0.66666667 | H33: 0.5 | I33: 0.4 | J33: 0.4 | K33: 0.33333333 | L33: 0.33333333 | M33: 0.33333333 | N33: 0.28571429
E34: =AVERAGE(E24:E33) -> 0.4 | F34: =AVERAGE(F24:F33) -> 0.45 | G34: =AVERAGE(G24:G33) -> 0.4 | H34: =AVERAGE(H24:H33) -> 0.425 | I34: =AVERAGE(I24:I33) -> 0.43 | J34: =AVERAGE(J24:J33) -> 0.43333333 | K34: =AVERAGE(K24:K33) -> 0.41666667 | L34: =AVERAGE(L24:L33) -> 0.40714286 | ... N34: =AVERAGE(N24:N33) -> 0.36551587
A35: 0 | B35: хочу тур по культурной столице России, с посещением окрестных достопримечательностей | C35: [2, 3, 4, 5, 6, 7, 8, 23, 24, 25, 26, 27, 28, 125, 126, 201] | D35: [np.int64(117), np.int64(33), np.int64(126), np.int64(43), np.int64(111), np.int64(194), np.int64(197)] | E35: 0 | F35: 0.5 | G35: 0.33333333 | H35: 0.25 | I35: 0.25 | J35: 0.25 | K35: 0.25 | L35: 0.2 | M35: 0.16666667 | N35: 0.14285714
A36: 1 | B36: Интересует тур в один из древнейших городов России, связанный имуществом родителей величайшего поэтв золотого века российской литературы | C36: [100, 101, 102, 103, 104, 105, 106, 107] | D36: [np.int64(109), np.int64(115), np.int64(43), np.int64(164), np.int64(116)] | E36: 0 | F36: 0 | G36: 0 | H36: 0 | I36: 0 | J36: 0 | K36: 0 | L36: 0 | M36: 0 | N36: 0
A37: 2 | B37: тур по северо-западу России, с посещением мест, где река с грохотом обрушивается вниз, старинного курорта с целебными источниками и обзорной экскурсией по столице региона. | C37: [9, 44, 58, 156, 201] | D37: [np.int64(16), np.int64(6), np.int64(126), np.int64(113), np.int64(42), np.int64(56), np.int64(126), np.int64(12), np.int64(33)] | E37: 0 | F37: 0 | G37: 0 | H37: 0 | I37: 0 | J37: 0 | K37: 0 | L37: 0 | M37: 0 | N37: 0
A38: 3 | B38: Ищу тур по главному городу Приморья с обзорной экскурсией по центру и парку дикой природы с дальневосточными животными | C38: [46, 118, 119, 182, 183, 184, 196, 212, 213, 214] | D38: [np.int64(0), np.int64(126), np.int64(46), np.int64(118), np.int64(174), np.int64(116), np.int64(199), np.int64(99), np.int64(213), np.int64(122)] | E38: 0 | F38: 0 | G38: 0.33333333 | H38: 0.5 | I38: 0.4 | J38: 0.33333333 | K38: 0.28571429 | L38: 0.25 | M38: 0.33333333 | N38: 0.3
A39: 4 | B39: тур по столице России, включающий в себя наиболее популярные достопримечательности | C39: [0, 1] | D39: [np.int64(153), np.int64(43), np.int64(10), np.int64(11), np.int64(126), np.int64(174), np.int64(127), np.int64(25)] | E39: 0 | F39: 0 | G39: 0 | H39: 0 | I39: 0 | J39: 0 | K39: 0 | L39: 0 | M39: 0 | N39: 0
A40: 5 | B40: тур по северо-западу России, по местам добычи минералов, известных своими целебными свойствами | C40: [9, 156] | D40: [np.int64(43), np.int64(199), np.int64(174), np.int64(41), np.int64(166), np.int64(175), np.int64(50), np.int64(191), np.int64(191), np.int64(49)] | E40: 0 | F40: 0 | G40: 0 | H40: 0 | I40: 0 | J40: 0 | K40: 0 | L40: 0 | M40: 0 | N40: 0
...

Sheet alt_qwen3_08B
A1: id | B1: question | C1: relv | D1: ret_chunks | E1: acc_1 | F1: acc_2 | G1: acc_3 | H1: acc_4 | I1: acc_5 | J1: acc_6 | K1: acc_7 | L1: acc_8 | M1: acc_9 | N1: acc_10
A2: 0 | B2: Какой вес имеет "Висячий камень" в парке Ергаки? | C2: [90, 123, 149, 190] | D2: [123, 90, 149, 190, 123, 190, 89, 47, 149, 190] | E2: 1 | F2: 1 | G2: 1 | H2: 1 | I2: 1 | J2: 1 | K2: 1 | L2: 1 | M2: 1 | N2: 1
A3: 1 | B3: Какова длина "Висячего камня" в парке Ергаки? | C3: [90, 123, 149, 190] | D3: [190, 123, 90, 47, 190, 89, 149, 149, 190, 90] | E3: 1 | F3: 1 | G3: 1 | H3: 1 | I3: 1 | J3: 1 | K3: 1 | L3: 1 | M3: 1 | N3: 1
A4: 2 | B4: Сколько ступеней в лестнице музея "Оглахты"? | C4: [47, 48, 89, 90, 147, 151] | D4: [149, 90, 47, 48, 147, 120, 122, 175, 151, 321] | E4: 0 | F4: 1 | G4: 1 | H4: 1 | I4: 1 | J4: 1 | K4: 1 | L4: 1 | M4: 1 | N4: 1
A5: 3 | B5: Сколько видов сыра предлагает сыроварня Deutsches Haus в Немане? | C5: [33] | D5: [307, 33, 309, 311, 310, 312, 90, 261, 240, np.int64(31)] | E5: 1 | F5: 1 | G5: 1 | H5: 1 | I5: 1 | J5: 1 | K5: 1 | L5: 1 | M5: 1 | N5: 1
A6: 4 | B6: Сколько экспонатов в собрании Национального музея Республики Татарстан? | C6: [39] | D6: [152, 18, 39, 13, 20, 19, 154, 155, np.int64(155), np.int64(47)] | E6: 0 | F6: 0 | G6: 0 | H6: 0 | I6: 0 | J6: 0 | K6: 1 | L6: 1 | M6: 1 | N6: 1
A7: 5 | B7: Сколько порогов проходят при сплаве по реке Катунь? | C7: [30, 31] | D7: [29, 30, 215, 218, 193, 93, np.int64(29), np.int64(193), np.int64(192), np.int64(157)] | E7: 1 | F7: 1 | G7: 1 | H7: 1 | I7: 1 | J7: 1 | K7: 1 | L7: 1 | M7: 1 | N7: 1
A8: 6 | B8: Сколько островов входит в экскурсию "Семь чудес Чивыркуйского залива"? | C8: [41] | D8: [288, 41, 105, 124, 49, 139, 46, 214, 83, np.int64(181)] | E8: 1 | F8: 1 | G8: 1 | H8: 1 | I8: 1 | J8: 1 | K8: 1 | L8: 1 | M8: 1 | N8: 1
A9: 7 | B9: Сколько бухт посещают во время экскурсии "Семь чудес Чивыркуйского залива"? | C9: [41] | D9: [29, 362, 365, 41, 216, 199, np.int64(180), np.int64(213), np.int64(182), np.int64(182)] | E9: 1 | F9: 1 | G9: 1 | H9: 1 | I9: 1 | J9: 1 | K9: 1 | L9: 1 | M9: 1 | N9: 1
A10: 8 | B10: Сколько источников с целебной водой можно попробовать на курорте "Марциальные Воды"? | C10: [9, 58, 156] | D10: [9, 156, 134, 9, 179, 209, 84, 82, 225, np.int64(114)] | E10: 1 | F10: 1 | G10: 1 | H10: 1 | I10: 1 | J10: 1 | K10: 1 | L10: 1 | M10: 1 | N10: 1
A11: 9 | B11: Сколько живописных и графических работ представлено в галерее Константина Васильева? | C11: [15] | D11: [152, 14, 15, 15, 15, 154, np.int64(223), np.int64(209), np.int64(182), np.int64(41)] | E11: 1 | F11: 1 | G11: 1 | H11: 1 | I11: 1 | J11: 1 | K11: 1 | L11: 1 | M11: 1 | N11: 1
E12: =AVERAGE(E2:E11) -> 0.8 | F12: =AVERAGE(F2:F11) -> 0.9 | G12: =AVERAGE(G2:G11) -> 0.9 | H12: =AVERAGE(H2:H11) -> 0.9 | I12: =AVERAGE(I2:I11) -> 0.9 | J12: =AVERAGE(J2:J11) -> 0.9 | K12: =AVERAGE(K2:K11) -> 1 | L12: =AVERAGE(L2:L11) -> 1 | ... N12: =AVERAGE(N2:N11) -> 1
A13: 0 | B13: Где хранится самый большой печатный Коран в мире, хранящийся в Болгаре? | C13: [12, 13, 16, 17, 18] | D13: [16, 365, 13, 17, 12, 149, 139, 17, np.int64(28), np.int64(142)] | E13: 1 | F13: 1 | G13: 1 | H13: 1 | I13: 1 | J13: 1 | K13: 1 | L13: 1 | M13: 1 | N13: 1
A14: 1 | B14: Какой минерал является гордостью Карелии | C14: [9, 156] | D14: [9, 156, 90, 138, 156, 156, 145, 191, 156, np.int64(21)] | E14: 0 | F14: 1 | G14: 1 | H14: 1 | I14: 1 | J14: 1 | K14: 1 | L14: 1 | M14: 1 | N14: 1
A15: 2 | B15: Какой тип пения демонстрируют в Тувинском национальном музыкальном центре? | C15: [45, 90, 123, 149, 150] | D15: [90, 149, 45, 123, 150, 90, 150, 45, 123, np.int64(16)] | E15: 1 | F15: 1 | G15: 1 | H15: 1 | I15: 1 | J15: 1 | K15: 1 | L15: 1 | M15: 1 | N15: 1
A16: 3 | B16: Какой напиток предлагают гостям в усадьбе Бюргера в Выборге? | C16: [8] | D16: [8, 99, 99, 99, 8, 99, 134, 286, 82, 359] | E16: 1 | F16: 1 | G16: 1 | H16: 1 | I16: 1 | J16: 1 | K16: 1 | L16: 1 | M16: 1 | N16: 1
A17: 4 | B17: Как называется традиционная тувинская выпечка, которую подают на ужине? | C17: [45, 90, 149, 150] | D17: [90, 150, 45, 90, 149, 149, 123, 45, 81, np.int64(153)] | E17: 1 | F17: 1 | G17: 1 | H17: 1 | I17: 1 | J17: 1 | K17: 1 | L17: 1 | M17: 1 | N17: 1
A18: 5 | B18: Как называется традиционная бурятская еда, которую подают в Тункинской долине? | C18: [45, 90, 149, 150] | D18: [42, 122, 122, 121, 196, 191, 137, 150, 149, 30] | E18: 0 | F18: 0 | G18: 0 | H18: 0 | I18: 0 | J18: 0 | K18: 0 | L18: 1 | M18: 1 | N18: 1
A19: 6 | B19: Как называется место в Хакасии, где можно увидеть след Будды? | C19: [45, 90, 149, 150] | D19: [149, 150, 123, 90, 45, 191, 139, 45, 50, 42] | E19: 1 | F19: 1 | G19: 1 | H19: 1 | I19: 1 | J19: 1 | K19: 1 | L19: 1 | M19: 1 | N19: 1
A20: 7 | B20: Какое поэтическое название используют для Телецкого озера в описаниях туров? | C20: [29, 30, 31, 92, 93, 94, 159, 194, 215, 216, 218] | D20: [92, 215, 30, 93, 215, 93, np.int64(171), np.int64(5), np.int64(224), np.int64(225)] | E20: 1 | F20: 1 | G20: 1 | H20: 1 | I20: 1 | J20: 1 | K20: 1 | L20: 1 | M20: 1 | N20: 1
A21: 8 | B21: Какая из буддийских ступ расположена на острове Огой? | C21: [57, 120, 124, 185] | D21: [122, 175, 50, 121, 69, 51, 137, 138, 120, 149] | E21: 0 | F21: 0 | G21: 0 | H21: 0 | I21: 0 | J21: 0 | K21: 0 | L21: 1 | M21: 1 | N21: 1
A22: 9 | B22: Какой уникальный архитектурный стиль характеризует библиотеку Алвара Аалто в Выборге? | C22: [8] | D22: [8, 99, 8, 18, 8, 149, 327, 267, 93, 265] | E22: 1 | F22: 1 | G22: 1 | H22: 1 | I22: 1 | J22: 1 | K22: 1 | L22: 1 | M22: 1 | N22: 1
E23: =AVERAGE(E13:E22) -> 0.7 | F23: =AVERAGE(F13:F22) -> 0.8 | G23: =AVERAGE(G13:G22) -> 0.8 | H23: =AVERAGE(H13:H22) -> 0.8 | I23: =AVERAGE(I13:I22) -> 0.8 | J23: =AVERAGE(J13:J22) -> 0.8 | K23: =AVERAGE(K13:K22) -> 0.8 | L23: =AVERAGE(L13:L22) -> 1 | ... N23: =AVERAGE(N13:N22) -> 1
A24: 0 | B24: Какие два моста являются символами Владивостока? | C24: [46, 118, 119, 182, 183, 184, 196, 212, 213, 214] | D24: [119, 183, 214, 119, 212, 118, 184, 212, 182, 183] | E24: 1 | F24: 1 | G24: 1 | H24: 1 | I24: 1 | J24: 1 | K24: 1 | L24: 1 | M24: 1 | N24: 1
A25: 1 | B25: Какие залы можно осмотреть в Храме всех религий? | C25: [13, 39, 40, 54, 55, 152, 153, 154, 155] | D25: [246, 40, 228, 13, 231, 240, np.int64(191), np.int64(54), np.int64(108), np.int64(5)] | E25: 1 | F25: 1 | G25: 1 | H25: 1 | I25: 1 | J25: 1 | K25: 1 | L25: 1 | M25: 1 | N25: 1
A26: 2 | B26: Блюда из каких виды морских обитателей дегустируют во Владивостоке? | C26: [46, 196, 212, 213] | D26: [46, 213, 212, 196, 214, 196, 118, 183, 119, 196] | E26: 1 | F26: 1 | G26: 1 | H26: 1 | I26: 1 | J26: 1 | K26: 1 | L26: 1 | M26: 1 | N26: 1
A27: 3 | B27: Какие животные обитают в сафари-парке Шкотово? | C27: [46, 118, 119, 214] | D27: [119, 196, 214, 46, 214, 118, 182, 118, 172, 201] | E27: 1 | F27: 1 | G27: 1 | H27: 1 | I27: 1 | J27: 1 | K27: 1 | L27: 1 | M27: 1 | N27: 1
A28: 4 | B28: Что чаще всего посещают во время экскурсии в Царское Село? | C28: [3, 4, 6, 7, 27, 28, 44, 201] | D28: [27, 27, 3, 6, 44, 201, 4, 0, np.int64(4), np.int64(88)] | E28: 1 | F28: 1 | G28: 1 | H28: 1 | I28: 1 | J28: 1 | K28: 1 | L28: 1 | M28: 1 | N28: 1
A29: 5 | B29: Что включает в себя экскурсия в Эрмитаж? | C29: [2, 3, 4, 5, 6, 7, 28, 44, 99, 125, 201] | D29: [307, 201, 3, 28, 2, 99, 6, 305, np.int64(201), np.int64(7)] | E29: 1 | F29: 1 | G29: 1 | H29: 1 | I29: 1 | J29: 1 | K29: 1 | L29: 1 | M29: 1 | N29: 1
A30: 6 | B30: Какие объекты посещают во время экскурсии по Свияжску? | C30: [10, 11, 12, 13, 14, 15, 16, 17, 18, 19, 20, 40, 54, 55, 152, 153, 154, 155] | D30: [10, 14, 40, 152, np.int64(30), np.int64(51), np.int64(191), np.int64(175), np.int64(15), np.int64(50)] | E30: 1 | F30: 1 | G30: 1 | H30: 1 | I30: 1 | J30: 1 | K30: 1 | L30: 1 | M30: 1 | N30: 1
A31: 7 | B31: Какие сувениры можно приобрести в Йошкар-Оле? | C31: [16, 17, 18, 19, 20] | D31: [128, 16, 17, 19, 90, 68, 50, np.int64(30), np.int64(113), np.int64(218)] | E31: 1 | F31: 1 | G31: 1 | H31: 1 | I31: 1 | J31: 1 | K31: 1 | L31: 1 | M31: 1 | N31: 1
A32: 8 | B32: на что можно посмотреть в Кунсткамере? | C32: [23, 24, 25, 26, 27, 28] | D32: [153, 310, 37, 45, 154, 152, 54, np.int64(223), np.int64(138), np.int64(170)] | E32: 0 | F32: 0 | G32: 0 | H32: 0 | I32: 0 | J32: 0 | K32: 0 | L32: 0 | M32: 0 | N32: 0
A33: 9 | B33: Как называются постройки на острове Кижи? | C33: [44] | D33: [44, 69, 175, 50, 13, 54, 137, 113, 51, 184] | E33: 1 | F33: 1 | G33: 1 | H33: 1 | I33: 1 | J33: 1 | K33: 1 | L33: 1 | M33: 1 | N33: 1
E34: =AVERAGE(E24:E33) -> 0.9 | F34: =AVERAGE(F24:F33) -> 0.9 | G34: =AVERAGE(G24:G33) -> 0.9 | H34: =AVERAGE(H24:H33) -> 0.9 | I34: =AVERAGE(I24:I33) -> 0.9 | J34: =AVERAGE(J24:J33) -> 0.9 | K34: =AVERAGE(K24:K33) -> 0.9 | L34: =AVERAGE(L24:L33) -> 0.9 | ... N34: =AVERAGE(N24:N33) -> 0.9
A35: 0 | B35: хочу тур по культурной столице России, с посещением окрестных достопримечательностей | C35: [2, 3, 4, 5, 6, 7, 8, 23, 24, 25, 26, 27, 28, 125, 126, 201] | D35: [310, 108, 116, 20, 13, 19, np.int64(117), 109, 130, 309] | E35: 0 | F35: 0 | G35: 0 | H35: 0 | I35: 0 | J35: 0 | K35: 0 | L35: 0 | M35: 0 | N35: 0
A36: 1 | B36: Интересует тур в один из древнейших городов России, связанный имуществом родителей величайшего поэтв золотого века российской литературы | C36: [100, 101, 102, 103, 104, 105, 106, 107] | D36: [108, 116, 109, 108, 154, 230, 46, 114, 18, np.int64(115)] | E36: 0 | F36: 0 | G36: 0 | H36: 0 | I36: 0 | J36: 0 | K36: 0 | L36: 0 | M36: 0 | N36: 0
A37: 2 | B37: тур по северо-западу России, с посещением мест, где река с грохотом обрушивается вниз, старинного курорта с целебными источниками и обзорной экскурсией по столице региона. | C37: [9, 44, 58, 156, 201] | D37: [180, 9, 108, 109, 130, 156, 122, 67, np.int64(16), np.int64(6)] | E37: 0 | F37: 0 | G37: 0 | H37: 0 | I37: 1 | J37: 1 | K37: 1 | L37: 1 | M37: 1 | N37: 1
A38: 3 | B38: Ищу тур по главному городу Приморья с обзорной экскурсией по центру и парку дикой природы с дальневосточными животными | C38: [46, 118, 119, 182, 183, 184, 196, 212, 213, 214] | D38: [213, 118, 196, 306, 305, 304, 172, 9, 176, 46] | E38: 1 | F38: 1 | G38: 1 | H38: 1 | I38: 1 | J38: 1 | K38: 1 | L38: 1 | M38: 1 | N38: 1
A39: 4 | B39: тур по столице России, включающий в себя наиболее популярные достопримечательности | C39: [0, 1] | D39: [316, 108, 109, 306, 116, 304, 314, 305, 290, np.int64(153)] | E39: 0 | F39: 0 | G39: 0 | H39: 0 | I39: 0 | J39: 0 | K39: 0 | L39: 0 | M39: 0 | N39: 0
A40: 5 | B40: тур по северо-западу России, по местам добычи минералов, известных своими целебными свойствами | C40: [9, 156] | D40: [58, 156, 122, 109, 121, 108, 215, 120, 90, 94] | E40: 0 | F40: 1 | G40: 1 | H40: 1 | I40: 1 | J40: 1 | K40: 1 | L40: 1 | M40: 1 | N40: 1
...

Sheet alt_e5
A1: id | B1: question | C1: relv | D1: ret_chunks | E1: acc_1 | F1: acc_2 | G1: acc_3 | H1: acc_4 | I1: acc_5 | J1: acc_6 | K1: acc_7 | L1: acc_8 | M1: acc_9 | N1: acc_10
A2: 0 | B2: Какой вес имеет "Висячий камень" в парке Ергаки? | C2: [90, 123, 149, 190] | D2: [np.int64(123), np.int64(149), np.int64(190), np.int64(90), np.int64(123), np.int64(123), np.int64(58), np.int64(156), np.int64(90), np.int64(149)] | E2: 1 | F2: 1 | G2: 1 | H2: 1 | I2: 1 | J2: 1 | K2: 1 | L2: 1 | M2: 1 | N2: 1
A3: 1 | B3: Какова длина "Висячего камня" в парке Ергаки? | C3: [90, 123, 149, 190] | D3: [np.int64(123), np.int64(151), np.int64(58), np.int64(89), np.int64(156), np.int64(90), np.int64(149), np.int64(190), np.int64(156), np.int64(118)] | E3: 1 | F3: 1 | G3: 1 | H3: 1 | I3: 1 | J3: 1 | K3: 1 | L3: 1 | M3: 1 | N3: 1
A4: 2 | B4: Сколько ступеней в лестнице музея "Оглахты"? | C4: [47, 48, 89, 90, 147, 151] | D4: [np.int64(90), np.int64(48), np.int64(149), np.int64(47), np.int64(147), np.int64(47), np.int64(89), np.int64(149), np.int64(147), np.int64(9)] | E4: 1 | F4: 1 | G4: 1 | H4: 1 | I4: 1 | J4: 1 | K4: 1 | L4: 1 | M4: 1 | N4: 1
A5: 3 | B5: Сколько видов сыра предлагает сыроварня Deutsches Haus в Немане? | C5: [33] | D5: [np.int64(31), np.int64(33), np.int64(76), np.int64(74), np.int64(72), np.int64(79), np.int64(87), np.int64(88), np.int64(218)] | E5: 1 | F5: 1 | G5: 1 | H5: 1 | I5: 1 | J5: 1 | K5: 1 | L5: 1 | M5: 1 | N5: 1
A6: 4 | B6: Сколько экспонатов в собрании Национального музея Республики Татарстан? | C6: [39] | D6: [np.int64(39), np.int64(18), np.int64(155), np.int64(47), np.int64(182), np.int64(213), np.int64(58), np.int64(118), np.int64(127), np.int64(184)] | E6: 1 | F6: 1 | G6: 1 | H6: 1 | I6: 1 | J6: 1 | K6: 1 | L6: 1 | M6: 1 | N6: 1
A7: 5 | B7: Сколько порогов проходят при сплаве по реке Катунь? | C7: [30, 31] | D7: [np.int64(30), np.int64(29), np.int64(193), np.int64(192), np.int64(218), np.int64(157), np.int64(158), np.int64(193), np.int64(159)] | E7: 1 | F7: 1 | G7: 1 | H7: 1 | I7: 1 | J7: 1 | K7: 1 | L7: 1 | M7: 1 | N7: 1
A8: 6 | B8: Сколько островов входит в экскурсию "Семь чудес Чивыркуйского залива"? | C8: [41] | D8: [np.int64(181), np.int64(41), np.int64(184), np.int64(163), np.int64(212), np.int64(118), np.int64(2), np.int64(225), np.int64(115)] | E8: 1 | F8: 1 | G8: 1 | H8: 1 | I8: 1 | J8: 1 | K8: 1 | L8: 1 | M8: 1 | N8: 1
A9: 7 | B9: Сколько бухт посещают во время экскурсии "Семь чудес Чивыркуйского залива"? | C9: [41] | D9: [np.int64(180), np.int64(41), np.int64(213), np.int64(182), np.int64(182), np.int64(126), np.int64(212), np.int64(5), np.int64(174)] | E9: 1 | F9: 1 | G9: 1 | H9: 1 | I9: 1 | J9: 1 | K9: 1 | L9: 1 | M9: 1 | N9: 1
A10: 8 | B10: Сколько источников с целебной водой можно попробовать на курорте "Марциальные Воды"? | C10: [9, 58, 156] | D10: [np.int64(156), np.int64(114), np.int64(108), np.int64(109), np.int64(82), np.int64(205), np.int64(163), np.int64(134), np.int64(9), np.int64(166)] | E10: 1 | F10: 1 | G10: 1 | H10: 1 | I10: 1 | J10: 1 | K10: 1 | L10: 1 | M10: 1 | N10: 1
A11: 9 | B11: Сколько живописных и графических работ представлено в галерее Константина Васильева? | C11: [15] | D11: [np.int64(15), np.int64(15), np.int64(223), np.int64(209), np.int64(182), np.int64(41), np.int64(206), np.int64(176), np.int64(166), np.int64(187)] | E11: 1 | F11: 1 | G11: 1 | H11: 1 | I11: 1 | J11: 1 | K11: 1 | L11: 1 | M11: 1 | N11: 1
E12: =AVERAGE(E2:E11) -> 1 | F12: =AVERAGE(F2:F11) -> 1 | G12: =AVERAGE(G2:G11) -> 1 | H12: =AVERAGE(H2:H11) -> 1 | I12: =AVERAGE(I2:I11) -> 1 | J12: =AVERAGE(J2:J11) -> 1 | K12: =AVERAGE(K2:K11) -> 1 | L12: =AVERAGE(L2:L11) -> 1 | ... N12: =AVERAGE(N2:N11) -> 1
A13: 0 | B13: Где хранится самый большой печатный Коран в мире, хранящийся в Болгаре? | C13: [12, 13, 16, 17, 18] | D13: [np.int64(28), np.int64(18), np.int64(13), np.int64(12), np.int64(17), np.int64(142)] | E13: 1 | F13: 1 | G13: 1 | H13: 1 | I13: 1 | J13: 1 | K13: 1 | L13: 1 | M13: 1 | N13: 1
A14: 1 | B14: Какой минерал является гордостью Карелии | C14: [9, 156] | D14: [np.int64(21), np.int64(9), np.int64(156), np.int64(156), np.int64(42), np.int64(194), np.int64(42), np.int64(7), np.int64(186)] | E14: 1 | F14: 1 | G14: 1 | H14: 1 | I14: 1 | J14: 1 | K14: 1 | L14: 1 | M14: 1 | N14: 1
A15: 2 | B15: Какой тип пения демонстрируют в Тувинском национальном музыкальном центре? | C15: [45, 90, 123, 149, 150] | D15: [np.int64(90), np.int64(16), np.int64(17), np.int64(45), np.int64(123), np.int64(149), np.int64(18), np.int64(20), np.int64(19)] | E15: 0 | F15: 0 | G15: 1 | H15: 1 | I15: 1 | J15: 1 | K15: 1 | L15: 1 | M15: 1 | N15: 1
A16: 3 | B16: Какой напиток предлагают гостям в усадьбе Бюргера в Выборге? | C16: [8] | D16: [np.int64(8), np.int64(99), np.int64(99), np.int64(105), np.int64(104), np.int64(137), np.int64(123), np.int64(90), np.int64(45), np.int64(89)] | E16: 1 | F16: 1 | G16: 1 | H16: 1 | I16: 1 | J16: 1 | K16: 1 | L16: 1 | M16: 1 | N16: 1
A17: 4 | B17: Как называется традиционная тувинская выпечка, которую подают на ужине? | C17: [45, 90, 149, 150] | D17: [np.int64(153), np.int64(15), np.int64(149), np.int64(147), np.int64(223), np.int64(89), np.int64(93)] | E17: 1 | F17: 1 | G17: 1 | H17: 1 | I17: 1 | J17: 1 | K17: 1 | L17: 1 | M17: 1 | N17: 1
A18: 5 | B18: Как называется традиционная бурятская еда, которую подают в Тункинской долине? | C18: [45, 90, 149, 150] | D18: [np.int64(155), np.int64(15), np.int64(42), np.int64(183), np.int64(223), np.int64(191), np.int64(89)] | E18: 0 | F18: 0 | G18: 0 | H18: 0 | I18: 0 | J18: 0 | K18: 0 | L18: 0 | M18: 0 | N18: 0
A19: 6 | B19: Как называется место в Хакасии, где можно увидеть след Будды? | C19: [45, 90, 149, 150] | D19: [np.int64(15), np.int64(123), np.int64(150), np.int64(90), np.int64(45), np.int64(149), np.int64(147), np.int64(89), np.int64(223)] | E19: 0 | F19: 1 | G19: 1 | H19: 1 | I19: 1 | J19: 1 | K19: 1 | L19: 1 | M19: 1 | N19: 1
A20: 7 | B20: Какое поэтическое название используют для Телецкого озера в описаниях туров? | C20: [29, 30, 31, 92, 93, 94, 159, 194, 215, 216, 218] | D20: [np.int64(159), np.int64(171), np.int64(5), np.int64(93), np.int64(224), np.int64(225), np.int64(9)] | E20: 0 | F20: 1 | G20: 1 | H20: 1 | I20: 1 | J20: 1 | K20: 1 | L20: 1 | M20: 1 | N20: 1
A21: 8 | B21: Какая из буддийских ступ расположена на острове Огой? | C21: [57, 120, 124, 185] | D21: [np.int64(122), np.int64(121), np.int64(69), np.int64(137), np.int64(51), np.int64(50), np.int64(175), np.int64(121), np.int64(138), np.int64(138)] | E21: 0 | F21: 0 | G21: 0 | H21: 0 | I21: 0 | J21: 0 | K21: 0 | L21: 0 | M21: 0 | N21: 0
A22: 9 | B22: Какой уникальный архитектурный стиль характеризует библиотеку Алвара Аалто в Выборге? | C22: [8] | D22: [np.int64(8), np.int64(8), np.int64(99), np.int64(155), np.int64(18), np.int64(39), np.int64(11), np.int64(15), np.int64(54), np.int64(126)] | E22: 1 | F22: 1 | G22: 1 | H22: 1 | I22: 1 | J22: 1 | K22: 1 | L22: 1 | M22: 1 | N22: 1
E23: =AVERAGE(E13:E22) -> 0.5 | F23: =AVERAGE(F13:F22) -> 0.7 | G23: =AVERAGE(G13:G22) -> 0.8 | H23: =AVERAGE(H13:H22) -> 0.8 | I23: =AVERAGE(I13:I22) -> 0.8 | J23: =AVERAGE(J13:J22) -> 0.8 | K23: =AVERAGE(K13:K22) -> 0.8 | L23: =AVERAGE(L13:L22) -> 0.8 | ... N23: =AVERAGE(N13:N22) -> 0.8
A24: 0 | B24: Какие два моста являются символами Владивостока? | C24: [46, 118, 119, 182, 183, 184, 196, 212, 213, 214] | D24: [np.int64(182), np.int64(212), np.int64(119), np.int64(214), np.int64(212), np.int64(119), np.int64(15), np.int64(147), np.int64(183), np.int64(51)] | E24: 1 | F24: 1 | G24: 1 | H24: 1 | I24: 1 | J24: 1 | K24: 1 | L24: 1 | M24: 1 | N24: 1
A25: 1 | B25: Какие залы можно осмотреть в Храме всех религий? | C25: [13, 39, 40, 54, 55, 152, 153, 154, 155] | D25: [np.int64(40), np.int64(191), np.int64(54), np.int64(108), np.int64(13), np.int64(5), np.int64(15), np.int64(36), np.int64(99)] | E25: 0 | F25: 1 | G25: 1 | H25: 1 | I25: 1 | J25: 1 | K25: 1 | L25: 1 | M25: 1 | N25: 1
A26: 2 | B26: Блюда из каких виды морских обитателей дегустируют во Владивостоке? | C26: [46, 196, 212, 213] | D26: [np.int64(224), np.int64(184), np.int64(183), np.int64(139), np.int64(170), np.int64(213), np.int64(196), np.int64(50), np.int64(105)] | E26: 0 | F26: 0 | G26: 0 | H26: 0 | I26: 0 | J26: 0 | K26: 1 | L26: 1 | M26: 1 | N26: 1
A27: 3 | B27: Какие животные обитают в сафари-парке Шкотово? | C27: [46, 118, 119, 214] | D27: [np.int64(165), np.int64(178), np.int64(196), np.int64(15), np.int64(214), np.int64(119), np.int64(50), np.int64(46), np.int64(175), np.int64(191)] | E27: 0 | F27: 0 | G27: 0 | H27: 0 | I27: 1 | J27: 1 | K27: 1 | L27: 1 | M27: 1 | N27: 1
A28: 4 | B28: Что чаще всего посещают во время экскурсии в Царское Село? | C28: [3, 4, 6, 7, 27, 28, 44, 201] | D28: [np.int64(28), np.int64(6), np.int64(44), np.int64(201), np.int64(3), np.int64(4), np.int64(88), np.int64(7), np.int64(28)] | E28: 1 | F28: 1 | G28: 1 | H28: 1 | I28: 1 | J28: 1 | K28: 1 | L28: 1 | M28: 1 | N28: 1
A29: 5 | B29: Что включает в себя экскурсия в Эрмитаж? | C29: [2, 3, 4, 5, 6, 7, 28, 44, 99, 125, 201] | D29: [np.int64(201), np.int64(7), np.int64(201), np.int64(3), np.int64(28), np.int64(120), np.int64(44), np.int64(3), np.int64(4), np.int64(151)] | E29: 1 | F29: 1 | G29: 1 | H29: 1 | I29: 1 | J29: 1 | K29: 1 | L29: 1 | M29: 1 | N29: 1
A30: 6 | B30: Какие объекты посещают во время экскурсии по Свияжску? | C30: [10, 11, 12, 13, 14, 15, 16, 17, 18, 19, 20, 40, 54, 55, 152, 153, 154, 155] | D30: [np.int64(30), np.int64(51), np.int64(191), np.int64(175), np.int64(15), np.int64(50), np.int64(9), np.int64(68)] | E30: 0 | F30: 0 | G30: 0 | H30: 1 | I30: 1 | J30: 1 | K30: 1 | L30: 1 | M30: 1 | N30: 1
A31: 7 | B31: Какие сувениры можно приобрести в Йошкар-Оле? | C31: [16, 17, 18, 19, 20] | D31: [np.int64(30), np.int64(113), np.int64(218), np.int64(127), np.int64(217), np.int64(56), np.int64(47), np.int64(61), np.int64(59)] | E31: 0 | F31: 0 | G31: 0 | H31: 0 | I31: 0 | J31: 0 | K31: 0 | L31: 0 | M31: 0 | N31: 0
A32: 8 | B32: на что можно посмотреть в Кунсткамере? | C32: [23, 24, 25, 26, 27, 28] | D32: [np.int64(223), np.int64(138), np.int64(45), np.int64(170), np.int64(67), np.int64(197), np.int64(59), np.int64(31), np.int64(225), np.int64(69)] | E32: 0 | F32: 0 | G32: 0 | H32: 0 | I32: 0 | J32: 0 | K32: 0 | L32: 0 | M32: 0 | N32: 0
A33: 9 | B33: Как называются постройки на острове Кижи? | C33: [44] | D33: [np.int64(153), np.int64(14), np.int64(44), np.int64(44), np.int64(197), np.int64(5), np.int64(15)] | E33: 1 | F33: 1 | G33: 1 | H33: 1 | I33: 1 | J33: 1 | K33: 1 | L33: 1 | M33: 1 | N33: 1
E34: =AVERAGE(E24:E33) -> 0.4 | F34: =AVERAGE(F24:F33) -> 0.5 | G34: =AVERAGE(G24:G33) -> 0.5 | H34: =AVERAGE(H24:H33) -> 0.6 | I34: =AVERAGE(I24:I33) -> 0.7 | J34: =AVERAGE(J24:J33) -> 0.7 | K34: =AVERAGE(K24:K33) -> 0.8 | L34: =AVERAGE(L24:L33) -> 0.8 | ... N34: =AVERAGE(N24:N33) -> 0.8
A35: 0 | B35: хочу тур по культурной столице России, с посещением окрестных достопримечательностей | C35: [2, 3, 4, 5, 6, 7, 8, 23, 24, 25, 26, 27, 28, 125, 126, 201] | D35: [np.int64(117), np.int64(33), np.int64(126), np.int64(43), np.int64(111), np.int64(194), np.int64(197)] | E35: 0 | F35: 1 | G35: 1 | H35: 1 | I35: 1 | J35: 1 | K35: 1 | L35: 1 | M35: 1 | N35: 1
A36: 1 | B36: Интересует тур в один из древнейших городов России, связанный имуществом родителей величайшего поэтв золотого века российской литературы | C36: [100, 101, 102, 103, 104, 105, 106, 107] | D36: [np.int64(109), np.int64(115), np.int64(43), np.int64(164), np.int64(116)] | E36: 0 | F36: 0 | G36: 0 | H36: 0 | I36: 0 | J36: 0 | K36: 0 | L36: 0 | M36: 0 | N36: 0
A37: 2 | B37: тур по северо-западу России, с посещением мест, где река с грохотом обрушивается вниз, старинного курорта с целебными источниками и обзорной экскурсией по столице региона. | C37: [9, 44, 58, 156, 201] | D37: [np.int64(16), np.int64(6), np.int64(126), np.int64(113), np.int64(42), np.int64(56), np.int64(126), np.int64(12), np.int64(33)] | E37: 0 | F37: 0 | G37: 0 | H37: 0 | I37: 0 | J37: 0 | K37: 0 | L37: 0 | M37: 0 | N37: 0
A38: 3 | B38: Ищу тур по главному городу Приморья с обзорной экскурсией по центру и парку дикой природы с дальневосточными животными | C38: [46, 118, 119, 182, 183, 184, 196, 212, 213, 214] | D38: [np.int64(0), np.int64(126), np.int64(46), np.int64(118), np.int64(174), np.int64(116), np.int64(199), np.int64(99), np.int64(213), np.int64(122)] | E38: 0 | F38: 0 | G38: 1 | H38: 1 | I38: 1 | J38: 1 | K38: 1 | L38: 1 | M38: 1 | N38: 1
A39: 4 | B39: тур по столице России, включающий в себя наиболее популярные достопримечательности | C39: [0, 1] | D39: [np.int64(153), np.int64(43), np.int64(10), np.int64(11), np.int64(126), np.int64(174), np.int64(127), np.int64(25)] | E39: 0 | F39: 0 | G39: 0 | H39: 0 | I39: 0 | J39: 0 | K39: 0 | L39: 0 | M39: 0 | N39: 0
A40: 5 | B40: тур по северо-западу России, по местам добычи минералов, известных своими целебными свойствами | C40: [9, 156] | D40: [np.int64(43), np.int64(199), np.int64(174), np.int64(41), np.int64(166), np.int64(175), np.int64(50), np.int64(191), np.int64(191), np.int64(49)] | E40: 0 | F40: 0 | G40: 0 | H40: 0 | I40: 0 | J40: 0 | K40: 0 | L40: 0 | M40: 0 | N40: 0
...

Sheet res
A1: e5+bm25
A2: точность на N-документов | B2: ='e5'!E58 -> 0.51071429 | C2: ='e5'!F58 -> 0.46011905 | D2: ='e5'!G58 -> 0.39345238 | E2: ='e5'!H58 -> 0.35972222 | F2: ='e5'!I58 -> 0.34045635 | G2: ='e5'!J58 -> 0.325 | H2: ='e5'!K58 -> 0.30617347 | I2: ='e5'!L58 -> 0.28686933 | ... K2: ='e5'!N58 -> 0.25651219
A3: индикатор | B3: =alt_e5!E58 -> 0.51071429 | C3: =alt_e5!F58 -> 0.60952381 | D3: =alt_e5!G58 -> 0.65833333 | E3: =alt_e5!H58 -> 0.68333333 | F3: =alt_e5!I58 -> 0.7202381 | G3: =alt_e5!J58 -> 0.74404762 | H3: =alt_e5!K58 -> 0.79285714 | I3: =alt_e5!L58 -> 0.8047619 | ... K3: =alt_e5!N58 -> 0.8047619
A4: qwen3_08B+bm25
A5: точность на N-документов | B5: =qwen3_08B!E58 -> 0.65952381 | C5: =qwen3_08B!F58 -> 0.60952381 | D5: =qwen3_08B!G58 -> 0.53055556 | E5: =qwen3_08B!H58 -> 0.47857143 | F5: =qwen3_08B!I58 -> 0.4339881 | G5: =qwen3_08B!J58 -> 0.41845238 | H5: =qwen3_08B!K58 -> 0.3994898 | I5: =qwen3_08B!L58 -> 0.39300595 | ... K5: =qwen3_08B!N58 -> 0.36154762
A6: индикатор | B6: =alt_qwen3_08B!E58 -> 0.65952381 | C6: =alt_qwen3_08B!F58 -> 0.7452381 | D6: =alt_qwen3_08B!G58 -> 0.76904762 | E6: =alt_qwen3_08B!H58 -> 0.78095238 | F6: =alt_qwen3_08B!I58 -> 0.79285714 | G6: =alt_qwen3_08B!J58 -> 0.8047619 | H6: =alt_qwen3_08B!K58 -> 0.84166667 | I6: =alt_qwen3_08B!L58 -> 0.89166667 | ... K6: =alt_qwen3_08B!N58 -> 0.89166667
